<?xml version='1.0'?>
<sdf version='1.7'>
  <model name='drone_with_marker_75m'>
    <link name='iris_standoff_camera::iris::base_link'>
      <velocity_decay>
        <linear>0</linear>
        <angular>0</angular>
      </velocity_decay>
      <inertial>
        <pose>0 0 0 0 -0 0</pose>
        <mass>1.5</mass>
        <inertia>
          <ixx>0.008</ixx>
          <ixy>0</ixy>
          <ixz>0</ixz>
          <iyy>0.015</iyy>
          <iyz>0</iyz>
          <izz>0.017</izz>
        </inertia>
      </inertial>
      <pose>0 0 0.194923 0 -0 0</pose>
      <self_collide>0</self_collide>
      <enable_wind>0</enable_wind>
      <kinematic>0</kinematic>
      <visual name='base_link_visual'>
        <geometry>
          <mesh>
            <uri>model://iris_with_standoffs/meshes/iris.dae</uri>
          </mesh>
        </geometry>
        <material>
          <script>
            <name>Gazebo/DarkGrey</name>
            <uri>__default__</uri>
          </script>
          <shader type='pixel'/>
          <emissive>0 0 0 1</emissive>
        </material>
        <pose>0 0 0 0 -0 0</pose>
        <transparency>0</transparency>
        <cast_shadows>1</cast_shadows>
      </visual>
      <visual name='front_left_leg_visual'>
        <pose>0.123 0.22 -0.11 0 -0 0</pose>
        <geometry>
          <cylinder>
            <radius>0.005</radius>
            <length>0.17</length>
          </cylinder>
        </geometry>
        <material>
          <script>
            <name>Gazebo/FlatBlack</name>
            <uri>file://media/materials/scripts/gazebo.material</uri>
          </script>
          <shader type='pixel'/>
          <emissive>0 0 0 1</emissive>
        </material>
        <transparency>0</transparency>
        <cast_shadows>1</cast_shadows>
      </visual>
      <visual name='front_right_leg_visual'>
        <pose>0.123 -0.22 -0.11 0 -0 0</pose>
        <geometry>
          <cylinder>
            <radius>0.005</radius>
            <length>0.17</length>
          </cylinder>
        </geometry>
        <material>
          <script>
            <name>Gazebo/FlatBlack</name>
            <uri>file://media/materials/scripts/gazebo.material</uri>
          </script>
          <shader type='pixel'/>
          <emissive>0 0 0 1</emissive>
        </material>
        <transparency>0</transparency>
        <cast_shadows>1</cast_shadows>
      </visual>
      <visual name='rear_left_leg_visual'>
        <pose>-0.14 0.21 -0.11 0 -0 0</pose>
        <geometry>
          <cylinder>
            <radius>0.005</radius>
            <length>0.17</length>
          </cylinder>
        </geometry>
        <material>
          <script>
            <name>Gazebo/FlatBlack</name>
            <uri>file://media/materials/scripts/gazebo.material</uri>
          </script>
          <shader type='pixel'/>
          <emissive>0 0 0 1</emissive>
        </material>
        <transparency>0</transparency>
        <cast_shadows>1</cast_shadows>
      </visual>
      <visual name='rear_right_leg_visual'>
        <pose>-0.14 -0.21 -0.11 0 -0 0</pose>
        <geometry>
          <cylinder>
            <radius>0.005</radius>
            <length>0.17</length>
          </cylinder>
        </geometry>
        <material>
          <script>
            <name>Gazebo/FlatBlack</name>
            <uri>file://media/materials/scripts/gazebo.material</uri>
          </script>
          <shader type='pixel'/>
          <emissive>0 0 0 1</emissive>
        </material>
        <transparency>0</transparency>
        <cast_shadows>1</cast_shadows>
      </visual>
      <collision name='base_link_collision'>
        <laser_retro>0</laser_retro>
        <max_contacts>10</max_contacts>
        <pose>0 0 -0.08 0 -0 0</pose>
        <geometry>
          <box>
            <size>0.47 0.47 0.23</size>
          </box>
        </geometry>
        <surface>
          <friction>
            <ode>
              <mu>1</mu>
              <mu2>1</mu2>
              <fdir1>0 0 0</fdir1>
              <slip1>0</slip1>
              <slip2>0</slip2>
            </ode>
            <torsional>
              <coefficient>1</coefficient>
              <patch_radius>0</patch_radius>
              <surface_radius>0</surface_radius>
              <use_patch_radius>1</use_patch_radius>
              <ode>
                <slip>0</slip>
              </ode>
            </torsional>
          </friction>
          <bounce>
            <restitution_coefficient>0</restitution_coefficient>
            <threshold>1e+06</threshold>
          </bounce>
          <contact>
            <collide_without_contact>0</collide_without_contact>
            <collide_without_contact_bitmask>1</collide_without_contact_bitmask>
            <collide_bitmask>1</collide_bitmask>
            <ode>
              <soft_cfm>0</soft_cfm>
              <soft_erp>0.2</soft_erp>
              <kp>1e+13</kp>
              <kd>1</kd>
              <max_vel>100</max_vel>
              <min_depth>0.001</min_depth>
            </ode>
            <bullet>
              <split_impulse>1</split_impulse>
              <split_impulse_penetration_threshold>-0.01</split_impulse_penetration_threshold>
              <soft_cfm>0</soft_cfm>
              <soft_erp>0.2</soft_erp>
              <kp>1e+13</kp>
              <kd>1</kd>
            </bullet>
          </contact>
        </surface>
      </collision>
    </link>
    <link name='iris_standoff_camera::gimbal_small_2d::base_link'>
      <inertial>
        <mass>0.2</mass>
        <inertia>
          <ixx>0.0001</ixx>
          <ixy>0</ixy>
          <ixz>0</ixz>
          <iyy>0.0001</iyy>
          <iyz>0</iyz>
          <izz>0.0001</izz>
        </inertia>
        <pose>0 0 0 0 -0 0</pose>
      </inertial>
      <pose>0 -0.01 0.07 1.57 -0 1.57</pose>
      <self_collide>0</self_collide>
      <enable_wind>0</enable_wind>
      <kinematic>0</kinematic>
      <visual name='base_main_viz'>
        <geometry>
          <mesh>
            <scale>0.001 0.001 0.001</scale>
            <uri>model://gimbal_small_2d/meshes/base_main.dae</uri>
          </mesh>
        </geometry>
        <material>
          <script>
            <uri>file://media/materials/scripts/gazebo.material</uri>
            <name>Gazebo/FlatBlack</name>
          </script>
          <shader type='pixel'/>
        </material>
        <pose>0 0 0 0 -0 0</pose>
        <transparency>0</transparency>
        <cast_shadows>1</cast_shadows>
      </visual>
      <visual name='base_arm_viz'>
        <geometry>
          <mesh>
            <scale>0.001 0.001 0.001</scale>
            <uri>model://gimbal_small_2d/meshes/base_arm.dae</uri>
          </mesh>
        </geometry>
        <material>
          <script>
            <uri>file://media/materials/scripts/gazebo.material</uri>
            <name>Gazebo/FlatBlack</name>
          </script>
          <shader type='pixel'/>
        </material>
        <pose>0 0 0 0 -0 0</pose>
        <transparency>0</transparency>
        <cast_shadows>1</cast_shadows>
      </visual>
      <collision name='base_col'>
        <laser_retro>0</laser_retro>
        <max_contacts>10</max_contacts>
        <pose>0.01 0.075 -0.025 0 -0 0</pose>
        <geometry>
          <box>
            <size>0.1 0.05 0.15</size>
          </box>
        </geometry>
        <surface>
          <friction>
            <ode>
              <mu>1</mu>
              <mu2>1</mu2>
              <fdir1>0 0 0</fdir1>
              <slip1>0</slip1>
              <slip2>0</slip2>
            </ode>
            <torsional>
              <coefficient>1</coefficient>
              <patch_radius>0</patch_radius>
              <surface_radius>0</surface_radius>
              <use_patch_radius>1</use_patch_radius>
              <ode>
                <slip>0</slip>
              </ode>
            </torsional>
          </friction>
          <bounce>
            <restitution_coefficient>0</restitution_coefficient>
            <threshold>1e+06</threshold>
          </bounce>
          <contact>
            <collide_without_contact>0</collide_without_contact>
            <collide_without_contact_bitmask>1</collide_without_contact_bitmask>
            <collide_bitmask>1</collide_bitmask>
            <ode>
              <soft_cfm>0</soft_cfm>
              <soft_erp>0.2</soft_erp>
              <kp>1e+13</kp>
              <kd>1</kd>
              <max_vel>0.01</max_vel>
              <min_depth>0</min_depth>
            </ode>
            <bullet>
              <split_impulse>1</split_impulse>
              <split_impulse_penetration_threshold>-0.01</split_impulse_penetration_threshold>
              <soft_cfm>0</soft_cfm>
              <soft_erp>0.2</soft_erp>
              <kp>1e+13</kp>
              <kd>1</kd>
            </bullet>
          </contact>
        </surface>
      </collision>
    </link>
    <link name='iris_standoff_camera::gimbal_small_2d::tilt_link'>
      <inertial>
        <mass>0.01</mass>
        <inertia>
          <ixx>1e-05</ixx>
          <ixy>0</ixy>
          <ixz>0</ixz>
          <iyy>1e-05</iyy>
          <iyz>0</iyz>
          <izz>1e-05</izz>
        </inertia>
        <pose>0 0 0 0 -0 0</pose>
      </inertial>
      <sensor name='camera' type='camera'>
        <pose>0 0 0 -1.57 -1.57 0</pose>
        <camera>
          <horizontal_fov>2</horizontal_fov>
          <image>
            <width>640</width>
            <height>480</height>
          </image>
          <clip>
            <near>0.05</near>
            <far>15000</far>
          </clip>
        </camera>
        <always_on>1</always_on>
        <update_rate>10</update_rate>
        <visualize>1</visualize>
      </sensor>
      <pose>0 -0.01 0.07 1.57 -0 1.57</pose>
      <self_collide>0</self_collide>
      <enable_wind>0</enable_wind>
      <kinematic>0</kinematic>
      <visual name='camera_viz'>
        <pose>0 0 0.02 0 -0 0</pose>
        <geometry>
          <cylinder>
            <radius>0.025</radius>
            <length>0.05</length>
          </cylinder>
        </geometry>
        <material>
          <script>
            <uri>file://media/materials/scripts/gazebo.material</uri>
            <name>Gazebo/Grey</name>
          </script>
          <shader type='pixel'/>
        </material>
        <transparency>0</transparency>
        <cast_shadows>1</cast_shadows>
      </visual>
      <visual name='tilt_viz'>
        <pose>0 0 -0.005 0 -0 0</pose>
        <geometry>
          <mesh>
            <scale>0.001 0.001 0.001</scale>
            <uri>model://gimbal_small_2d/meshes/tilt.dae</uri>
          </mesh>
        </geometry>
        <material>
          <script>
            <uri>file://media/materials/scripts/gazebo.material</uri>
            <name>Gazebo/Grey</name>
          </script>
          <shader type='pixel'/>
        </material>
        <transparency>0</transparency>
        <cast_shadows>1</cast_shadows>
      </visual>
      <collision name='tilt_col'>
        <laser_retro>0</laser_retro>
        <max_contacts>10</max_contacts>
        <pose>0 0 -0.005 0 -0 0</pose>
        <geometry>
          <mesh>
            <uri>/home/yusuf/.gazebo/models/gimbal_small_2d/meshes/tilt.dae</uri>
            <scale>0.001 0.001 0.001</scale>
          </mesh>
        </geometry>
        <surface>
          <friction>
            <ode>
              <mu>1</mu>
              <mu2>1</mu2>
              <fdir1>0 0 0</fdir1>
              <slip1>0</slip1>
              <slip2>0</slip2>
            </ode>
            <torsional>
              <coefficient>1</coefficient>
              <patch_radius>0</patch_radius>
              <surface_radius>0</surface_radius>
              <use_patch_radius>1</use_patch_radius>
              <ode>
                <slip>0</slip>
              </ode>
            </torsional>
          </friction>
          <bounce>
            <restitution_coefficient>0</restitution_coefficient>
            <threshold>1e+06</threshold>
          </bounce>
          <contact>
            <collide_without_contact>0</collide_without_contact>
            <collide_without_contact_bitmask>1</collide_without_contact_bitmask>
            <collide_bitmask>1</collide_bitmask>
            <ode>
              <soft_cfm>0</soft_cfm>
              <soft_erp>0.2</soft_erp>
              <kp>1e+13</kp>
              <kd>1</kd>
              <max_vel>0.01</max_vel>
              <min_depth>0</min_depth>
            </ode>
            <bullet>
              <split_impulse>1</split_impulse>
              <split_impulse_penetration_threshold>-0.01</split_impulse_penetration_threshold>
              <soft_cfm>0</soft_cfm>
              <soft_erp>0.2</soft_erp>
              <kp>1e+13</kp>
              <kd>1</kd>
            </bullet>
          </contact>
        </surface>
      </collision>
      <collision name='camera_col'>
        <laser_retro>0</laser_retro>
        <max_contacts>10</max_contacts>
        <pose>0 0 0.02 0 -0 0</pose>
        <geometry>
          <cylinder>
            <radius>0.025</radius>
            <length>0.05</length>
          </cylinder>
        </geometry>
        <surface>
          <friction>
            <ode>
              <mu>1</mu>
              <mu2>1</mu2>
              <fdir1>0 0 0</fdir1>
              <slip1>0</slip1>
              <slip2>0</slip2>
            </ode>
            <torsional>
              <coefficient>1</coefficient>
              <patch_radius>0</patch_radius>
              <surface_radius>0</surface_radius>
              <use_patch_radius>1</use_patch_radius>
              <ode>
                <slip>0</slip>
              </ode>
            </torsional>
          </friction>
          <bounce>
            <restitution_coefficient>0</restitution_coefficient>
            <threshold>1e+06</threshold>
          </bounce>
          <contact>
            <collide_without_contact>0</collide_without_contact>
            <collide_without_contact_bitmask>1</collide_without_contact_bitmask>
            <collide_bitmask>1</collide_bitmask>
            <ode>
              <soft_cfm>0</soft_cfm>
              <soft_erp>0.2</soft_erp>
              <kp>1e+13</kp>
              <kd>1</kd>
              <max_vel>0.01</max_vel>
              <min_depth>0</min_depth>
            </ode>
            <bullet>
              <split_impulse>1</split_impulse>
              <split_impulse_penetration_threshold>-0.01</split_impulse_penetration_threshold>
              <soft_cfm>0</soft_cfm>
              <soft_erp>0.2</soft_erp>
              <kp>1e+13</kp>
              <kd>1</kd>
            </bullet>
          </contact>
        </surface>
      </collision>
    </link>
    <link name='iris_standoff_camera::iris::iris/ground_truth/odometry_sensorgt_link'>
      <pose>0 0 0.194923 0 -0 0</pose>
      <inertial>
        <pose>0 0 0 0 -0 0</pose>
        <mass>0.15</mass>
        <inertia>
          <ixx>0.0001</ixx>
          <ixy>0</ixy>
          <ixz>0</ixz>
          <iyy>0.0002</iyy>
          <iyz>0</iyz>
          <izz>0.0002</izz>
        </inertia>
      </inertial>
      <self_collide>0</self_collide>
      <enable_wind>0</enable_wind>
      <kinematic>0</kinematic>
    </link>
    <link name='iris_standoff_camera::iris::iris/imu_link'>
      <inertial>
        <pose>0 0 0 0 -0 0</pose>
        <mass>0.15</mass>
        <inertia>
          <ixx>1e-05</ixx>
          <ixy>0</ixy>
          <ixz>0</ixz>
          <iyy>2e-05</iyy>
          <iyz>0</iyz>
          <izz>2e-05</izz>
        </inertia>
      </inertial>
      <sensor name='imu_sensor' type='imu'>
        <pose>0 0 0 -3.14159 -0 0</pose>
        <always_on>1</always_on>
        <update_rate>1000</update_rate>
        <imu/>
      </sensor>
      <pose>0 0 0.194923 0 -0 0</pose>
      <self_collide>0</self_collide>
      <enable_wind>0</enable_wind>
      <kinematic>0</kinematic>
    </link>
    <link name='iris_standoff_camera::iris::rotor_0'>
      <pose>0.13 -0.22 0.217923 0 -0 0</pose>
      <inertial>
        <pose>0 0 0 0 -0 0</pose>
        <mass>0.025</mass>
        <inertia>
          <ixx>9.75e-06</ixx>
          <ixy>0</ixy>
          <ixz>0</ixz>
          <iyy>0.000166704</iyy>
          <iyz>0</iyz>
          <izz>0.000167604</izz>
        </inertia>
      </inertial>
      <gravity>1</gravity>
      <velocity_decay/>
      <self_collide>0</self_collide>
      <enable_wind>0</enable_wind>
      <kinematic>0</kinematic>
      <visual name='rotor_0_visual'>
        <pose>0 0 0 0 -0 0</pose>
        <geometry>
          <mesh>
            <scale>1 1 1</scale>
            <uri>model://iris_with_standoffs/meshes/iris_prop_ccw.dae</uri>
          </mesh>
        </geometry>
        <material>
          <script>
            <name>Gazebo/Blue</name>
            <uri>__default__</uri>
          </script>
          <shader type='pixel'/>
          <emissive>0 0 0 1</emissive>
        </material>
        <transparency>0</transparency>
        <cast_shadows>1</cast_shadows>
      </visual>
      <collision name='rotor_0_collision'>
        <laser_retro>0</laser_retro>
        <max_contacts>10</max_contacts>
        <pose>0 0 0 0 -0 0</pose>
        <geometry>
          <cylinder>
            <radius>0.1</radius>
            <length>0.005</length>
          </cylinder>
        </geometry>
        <surface>
          <friction>
            <ode>
              <mu>1</mu>
              <mu2>1</mu2>
              <fdir1>0 0 0</fdir1>
              <slip1>0</slip1>
              <slip2>0</slip2>
            </ode>
            <torsional>
              <coefficient>1</coefficient>
              <patch_radius>0</patch_radius>
              <surface_radius>0</surface_radius>
              <use_patch_radius>1</use_patch_radius>
              <ode>
                <slip>0</slip>
              </ode>
            </torsional>
          </friction>
          <bounce>
            <restitution_coefficient>0</restitution_coefficient>
            <threshold>1e+06</threshold>
          </bounce>
          <contact>
            <collide_without_contact>0</collide_without_contact>
            <collide_without_contact_bitmask>1</collide_without_contact_bitmask>
            <collide_bitmask>1</collide_bitmask>
            <ode>
              <soft_cfm>0</soft_cfm>
              <soft_erp>0.2</soft_erp>
              <kp>1e+13</kp>
              <kd>1</kd>
              <max_vel>0.01</max_vel>
              <min_depth>0</min_depth>
            </ode>
            <bullet>
              <split_impulse>1</split_impulse>
              <split_impulse_penetration_threshold>-0.01</split_impulse_penetration_threshold>
              <soft_cfm>0</soft_cfm>
              <soft_erp>0.2</soft_erp>
              <kp>1e+13</kp>
              <kd>1</kd>
            </bullet>
          </contact>
        </surface>
      </collision>
    </link>
    <link name='iris_standoff_camera::iris::rotor_1'>
      <pose>-0.13 0.2 0.217923 0 -0 0</pose>
      <inertial>
        <pose>0 0 0 0 -0 0</pose>
        <mass>0.025</mass>
        <inertia>
          <ixx>9.75e-06</ixx>
          <ixy>0</ixy>
          <ixz>0</ixz>
          <iyy>0.000166704</iyy>
          <iyz>0</iyz>
          <izz>0.000167604</izz>
        </inertia>
      </inertial>
      <gravity>1</gravity>
      <velocity_decay/>
      <self_collide>0</self_collide>
      <enable_wind>0</enable_wind>
      <kinematic>0</kinematic>
      <visual name='rotor_1_visual'>
        <pose>0 0 0 0 -0 0</pose>
        <geometry>
          <mesh>
            <scale>1 1 1</scale>
            <uri>model://iris_with_standoffs/meshes/iris_prop_ccw.dae</uri>
          </mesh>
        </geometry>
        <material>
          <script>
            <name>Gazebo/DarkGrey</name>
            <uri>__default__</uri>
          </script>
          <shader type='pixel'/>
        </material>
        <transparency>0</transparency>
        <cast_shadows>1</cast_shadows>
      </visual>
      <collision name='rotor_1_collision'>
        <laser_retro>0</laser_retro>
        <max_contacts>10</max_contacts>
        <pose>0 0 0 0 -0 0</pose>
        <geometry>
          <cylinder>
            <radius>0.1</radius>
            <length>0.005</length>
          </cylinder>
        </geometry>
        <surface>
          <friction>
            <ode>
              <mu>1</mu>
              <mu2>1</mu2>
              <fdir1>0 0 0</fdir1>
              <slip1>0</slip1>
              <slip2>0</slip2>
            </ode>
            <torsional>
              <coefficient>1</coefficient>
              <patch_radius>0</patch_radius>
              <surface_radius>0</surface_radius>
              <use_patch_radius>1</use_patch_radius>
              <ode>
                <slip>0</slip>
              </ode>
            </torsional>
          </friction>
          <bounce>
            <restitution_coefficient>0</restitution_coefficient>
            <threshold>1e+06</threshold>
          </bounce>
          <contact>
            <collide_without_contact>0</collide_without_contact>
            <collide_without_contact_bitmask>1</collide_without_contact_bitmask>
            <collide_bitmask>1</collide_bitmask>
            <ode>
              <soft_cfm>0</soft_cfm>
              <soft_erp>0.2</soft_erp>
              <kp>1e+13</kp>
              <kd>1</kd>
              <max_vel>0.01</max_vel>
              <min_depth>0</min_depth>
            </ode>
            <bullet>
              <split_impulse>1</split_impulse>
              <split_impulse_penetration_threshold>-0.01</split_impulse_penetration_threshold>
              <soft_cfm>0</soft_cfm>
              <soft_erp>0.2</soft_erp>
              <kp>1e+13</kp>
              <kd>1</kd>
            </bullet>
          </contact>
        </surface>
      </collision>
    </link>
    <link name='iris_standoff_camera::iris::rotor_2'>
      <pose>0.13 0.22 0.217923 0 -0 0</pose>
      <inertial>
        <pose>0 0 0 0 -0 0</pose>
        <mass>0.025</mass>
        <inertia>
          <ixx>9.75e-06</ixx>
          <ixy>0</ixy>
          <ixz>0</ixz>
          <iyy>0.000166704</iyy>
          <iyz>0</iyz>
          <izz>0.000167604</izz>
        </inertia>
      </inertial>
      <gravity>1</gravity>
      <velocity_decay/>
      <self_collide>0</self_collide>
      <enable_wind>0</enable_wind>
      <kinematic>0</kinematic>
      <visual name='rotor_2_visual'>
        <pose>0 0 0 0 -0 0</pose>
        <geometry>
          <mesh>
            <scale>1 1 1</scale>
            <uri>model://iris_with_standoffs/meshes/iris_prop_cw.dae</uri>
          </mesh>
        </geometry>
        <material>
          <script>
            <name>Gazebo/Blue</name>
            <uri>__default__</uri>
          </script>
          <shader type='pixel'/>
        </material>
        <transparency>0</transparency>
        <cast_shadows>1</cast_shadows>
      </visual>
      <collision name='rotor_2_collision'>
        <laser_retro>0</laser_retro>
        <max_contacts>10</max_contacts>
        <pose>0 0 0 0 -0 0</pose>
        <geometry>
          <cylinder>
            <radius>0.1</radius>
            <length>0.005</length>
          </cylinder>
        </geometry>
        <surface>
          <friction>
            <ode>
              <mu>1</mu>
              <mu2>1</mu2>
              <fdir1>0 0 0</fdir1>
              <slip1>0</slip1>
              <slip2>0</slip2>
            </ode>
            <torsional>
              <coefficient>1</coefficient>
              <patch_radius>0</patch_radius>
              <surface_radius>0</surface_radius>
              <use_patch_radius>1</use_patch_radius>
              <ode>
                <slip>0</slip>
              </ode>
            </torsional>
          </friction>
          <bounce>
            <restitution_coefficient>0</restitution_coefficient>
            <threshold>1e+06</threshold>
          </bounce>
          <contact>
            <collide_without_contact>0</collide_without_contact>
            <collide_without_contact_bitmask>1</collide_without_contact_bitmask>
            <collide_bitmask>1</collide_bitmask>
            <ode>
              <soft_cfm>0</soft_cfm>
              <soft_erp>0.2</soft_erp>
              <kp>1e+13</kp>
              <kd>1</kd>
              <max_vel>0.01</max_vel>
              <min_depth>0</min_depth>
            </ode>
            <bullet>
              <split_impulse>1</split_impulse>
              <split_impulse_penetration_threshold>-0.01</split_impulse_penetration_threshold>
              <soft_cfm>0</soft_cfm>
              <soft_erp>0.2</soft_erp>
              <kp>1e+13</kp>
              <kd>1</kd>
            </bullet>
          </contact>
        </surface>
      </collision>
    </link>
    <link name='iris_standoff_camera::iris::rotor_3'>
      <pose>-0.13 -0.2 0.217923 0 -0 0</pose>
      <inertial>
        <pose>0 0 0 0 -0 0</pose>
        <mass>0.025</mass>
        <inertia>
          <ixx>9.75e-06</ixx>
          <ixy>0</ixy>
          <ixz>0</ixz>
          <iyy>0.000166704</iyy>
          <iyz>0</iyz>
          <izz>0.000167604</izz>
        </inertia>
      </inertial>
      <gravity>1</gravity>
      <velocity_decay/>
      <self_collide>0</self_collide>
      <enable_wind>0</enable_wind>
      <kinematic>0</kinematic>
      <visual name='rotor_3_visual'>
        <pose>0 0 0 0 -0 0</pose>
        <geometry>
          <mesh>
            <scale>1 1 1</scale>
            <uri>model://iris_with_standoffs/meshes/iris_prop_cw.dae</uri>
          </mesh>
        </geometry>
        <material>
          <script>
            <name>Gazebo/DarkGrey</name>
            <uri>__default__</uri>
          </script>
          <shader type='pixel'/>
          <emissive>0 0 0 1</emissive>
        </material>
        <transparency>0</transparency>
        <cast_shadows>1</cast_shadows>
      </visual>
      <collision name='rotor_3_collision'>
        <laser_retro>0</laser_retro>
        <max_contacts>10</max_contacts>
        <pose>0 0 0 0 -0 0</pose>
        <geometry>
          <cylinder>
            <radius>0.1</radius>
            <length>0.005</length>
          </cylinder>
        </geometry>
        <surface>
          <friction>
            <ode>
              <mu>1</mu>
              <mu2>1</mu2>
              <fdir1>0 0 0</fdir1>
              <slip1>0</slip1>
              <slip2>0</slip2>
            </ode>
            <torsional>
              <coefficient>1</coefficient>
              <patch_radius>0</patch_radius>
              <surface_radius>0</surface_radius>
              <use_patch_radius>1</use_patch_radius>
              <ode>
                <slip>0</slip>
              </ode>
            </torsional>
          </friction>
          <bounce>
            <restitution_coefficient>0</restitution_coefficient>
            <threshold>1e+06</threshold>
          </bounce>
          <contact>
            <collide_without_contact>0</collide_without_contact>
            <collide_without_contact_bitmask>1</collide_without_contact_bitmask>
            <collide_bitmask>1</collide_bitmask>
            <ode>
              <soft_cfm>0</soft_cfm>
              <soft_erp>0.2</soft_erp>
              <kp>1e+13</kp>
              <kd>1</kd>
              <max_vel>0.01</max_vel>
              <min_depth>0</min_depth>
            </ode>
            <bullet>
              <split_impulse>1</split_impulse>
              <split_impulse_penetration_threshold>-0.01</split_impulse_penetration_threshold>
              <soft_cfm>0</soft_cfm>
              <soft_erp>0.2</soft_erp>
              <kp>1e+13</kp>
              <kd>1</kd>
            </bullet>
          </contact>
        </surface>
      </collision>
    </link>
    <link name='link_0'>
      <inertial>
        <mass>1</mass>
        <inertia>
          <ixx>0.145833</ixx>
          <ixy>0</ixy>
          <ixz>0</ixz>
          <iyy>0.145833</iyy>
          <iyz>0</iyz>
          <izz>0.125</izz>
        </inertia>
        <pose>0 0 0 0 -0 0</pose>
      </inertial>
      <pose>-0.003653 -0.008274 0.097795 0 -0 0</pose>
      <gravity>1</gravity>
      <self_collide>0</self_collide>
      <kinematic>0</kinematic>
      <enable_wind>0</enable_wind>
      <visual name='visual'>
        <pose>0 0 0 0 -0 0</pose>
        <geometry>
          <cylinder>
            <radius>7.5</radius>
            <length>0.2</length>
          </cylinder>
        </geometry>
        <material>
          <lighting>1</lighting>
          <script>
            <uri>file://media/materials/scripts/gazebo.material</uri>
            <name>Gazebo/Grey</name>
          </script>
          <shader type='pixel'>
            <normal_map>__default__</normal_map>
          </shader>
          <ambient>0.3 0.3 0.3 1</ambient>
          <diffuse>0.7 0.7 0.7 1</diffuse>
          <specular>0.01 0.01 0.01 1</specular>
          <emissive>0 0 0 1</emissive>
        </material>
        <transparency>0.6</transparency>
        <cast_shadows>1</cast_shadows>
      </visual>
    </link>
    <joint name='iris_standoff_camera::gimbal_small_2d::tilt_joint' type='revolute'>
      <parent>iris_standoff_camera::gimbal_small_2d::base_link</parent>
      <child>iris_standoff_camera::gimbal_small_2d::tilt_link</child>
      <pose>0 0 0.02 0 -0 0</pose>
      <axis>
        <xyz>1 0 -0</xyz>
        <limit>
          <lower>-0.1</lower>
          <upper>3.14159</upper>
          <effort>10</effort>
          <velocity>-1</velocity>
        </limit>
        <dynamics>
          <spring_reference>0</spring_reference>
          <spring_stiffness>0</spring_stiffness>
          <damping>0.5</damping>
          <friction>0</friction>
        </dynamics>
      </axis>
      <physics>
        <ode>
          <limit>
            <cfm>0</cfm>
            <erp>0.2</erp>
          </limit>
          <suspension>
            <cfm>0</cfm>
            <erp>0.2</erp>
          </suspension>
        </ode>
      </physics>
    </joint>
    <joint name='iris_standoff_camera::iris::iris/ground_truth/odometry_sensorgt_joint' type='revolute'>
      <parent>iris_standoff_camera::iris::base_link</parent>
      <child>iris_standoff_camera::iris::iris/ground_truth/odometry_sensorgt_link</child>
      <pose>0 0 0 0 -0 0</pose>
      <axis>
        <xyz>0 0 1</xyz>
        <limit>
          <lower>0</lower>
          <upper>0</upper>
          <effort>0</effort>
          <velocity>0</velocity>
        </limit>
        <dynamics>
          <spring_reference>0</spring_reference>
          <spring_stiffness>0</spring_stiffness>
          <damping>1</damping>
          <friction>0</friction>
        </dynamics>
      </axis>
      <physics>
        <ode>
          <limit>
            <cfm>0</cfm>
            <erp>0.2</erp>
          </limit>
          <suspension>
            <cfm>0</cfm>
            <erp>0.2</erp>
          </suspension>
        </ode>
      </physics>
    </joint>
    <joint name='iris_standoff_camera::iris::iris/imu_joint' type='revolute'>
      <parent>iris_standoff_camera::iris::base_link</parent>
      <child>iris_standoff_camera::iris::iris/imu_link</child>
      <pose>0 0 0 0 -0 0</pose>
      <axis>
        <xyz>0 0 1</xyz>
        <limit>
          <lower>0</lower>
          <upper>0</upper>
          <effort>0</effort>
          <velocity>0</velocity>
        </limit>
        <dynamics>
          <spring_reference>0</spring_reference>
          <spring_stiffness>0</spring_stiffness>
          <damping>1</damping>
          <friction>0</friction>
        </dynamics>
      </axis>
      <physics>
        <ode>
          <limit>
            <cfm>0</cfm>
            <erp>0.2</erp>
          </limit>
          <suspension>
            <cfm>0</cfm>
            <erp>0.2</erp>
          </suspension>
        </ode>
      </physics>
    </joint>
    <joint name='iris_standoff_camera::iris::rotor_0_joint' type='revolute'>
      <parent>iris_standoff_camera::iris::base_link</parent>
      <child>iris_standoff_camera::iris::rotor_0</child>
      <pose>0 0 0 0 -0 0</pose>
      <axis>
        <xyz>0 0 1</xyz>
        <limit>
          <lower>-1e+16</lower>
          <upper>1e+16</upper>
          <effort>-1</effort>
          <velocity>-1</velocity>
        </limit>
        <dynamics>
          <spring_reference>0</spring_reference>
          <spring_stiffness>0</spring_stiffness>
          <damping>0.004</damping>
          <friction>0</friction>
        </dynamics>
      </axis>
      <physics>
        <ode>
          <limit>
            <cfm>0</cfm>
            <erp>0.2</erp>
          </limit>
          <suspension>
            <cfm>0</cfm>
            <erp>0.2</erp>
          </suspension>
        </ode>
      </physics>
    </joint>
    <joint name='iris_standoff_camera::iris::rotor_1_joint' type='revolute'>
      <parent>iris_standoff_camera::iris::base_link</parent>
      <child>iris_standoff_camera::iris::rotor_1</child>
      <pose>0 0 0 0 -0 0</pose>
      <axis>
        <xyz>0 0 1</xyz>
        <limit>
          <lower>-1e+16</lower>
          <upper>1e+16</upper>
          <effort>-1</effort>
          <velocity>-1</velocity>
        </limit>
        <dynamics>
          <spring_reference>0</spring_reference>
          <spring_stiffness>0</spring_stiffness>
          <damping>0.004</damping>
          <friction>0</friction>
        </dynamics>
      </axis>
      <physics>
        <ode>
          <limit>
            <cfm>0</cfm>
            <erp>0.2</erp>
          </limit>
          <suspension>
            <cfm>0</cfm>
            <erp>0.2</erp>
          </suspension>
        </ode>
      </physics>
    </joint>
    <joint name='iris_standoff_camera::iris::rotor_2_joint' type='revolute'>
      <parent>iris_standoff_camera::iris::base_link</parent>
      <child>iris_standoff_camera::iris::rotor_2</child>
      <pose>0 0 0 0 -0 0</pose>
      <axis>
        <xyz>0 0 1</xyz>
        <limit>
          <lower>-1e+16</lower>
          <upper>1e+16</upper>
          <effort>-1</effort>
          <velocity>-1</velocity>
        </limit>
        <dynamics>
          <spring_reference>0</spring_reference>
          <spring_stiffness>0</spring_stiffness>
          <damping>0.004</damping>
          <friction>0</friction>
        </dynamics>
      </axis>
      <physics>
        <ode>
          <limit>
            <cfm>0</cfm>
            <erp>0.2</erp>
          </limit>
          <suspension>
            <cfm>0</cfm>
            <erp>0.2</erp>
          </suspension>
        </ode>
      </physics>
    </joint>
    <joint name='iris_standoff_camera::iris::rotor_3_joint' type='revolute'>
      <parent>iris_standoff_camera::iris::base_link</parent>
      <child>iris_standoff_camera::iris::rotor_3</child>
      <pose>0 0 0 0 -0 0</pose>
      <axis>
        <xyz>0 0 1</xyz>
        <limit>
          <lower>-1e+16</lower>
          <upper>1e+16</upper>
          <effort>-1</effort>
          <velocity>-1</velocity>
        </limit>
        <dynamics>
          <spring_reference>0</spring_reference>
          <spring_stiffness>0</spring_stiffness>
          <damping>0.004</damping>
          <friction>0</friction>
        </dynamics>
      </axis>
      <physics>
        <ode>
          <limit>
            <cfm>0</cfm>
            <erp>0.2</erp>
          </limit>
          <suspension>
            <cfm>0</cfm>
            <erp>0.2</erp>
          </suspension>
        </ode>
      </physics>
    </joint>
    <joint name='iris_standoff_camera::iris_gimbal_mount' type='revolute'>
      <parent>iris_standoff_camera::iris::base_link</parent>
      <child>iris_standoff_camera::gimbal_small_2d::base_link</child>
      <pose>0 0 0 0 -0 0</pose>
      <axis>
        <xyz>0 1 0.000796</xyz>
        <limit>
          <lower>0</lower>
          <upper>0</upper>
          <effort>-1</effort>
          <velocity>-1</velocity>
        </limit>
        <dynamics>
          <spring_reference>0</spring_reference>
          <spring_stiffness>0</spring_stiffness>
          <damping>0</damping>
          <friction>0</friction>
        </dynamics>
      </axis>
      <physics>
        <ode>
          <limit>
            <cfm>0</cfm>
            <erp>0.2</erp>
          </limit>
          <suspension>
            <cfm>0</cfm>
            <erp>0.2</erp>
          </suspension>
        </ode>
      </physics>
    </joint>
    <joint name='link_0_JOINT_1' type='fixed'>
      <parent>link_0</parent>
      <child>iris_standoff_camera::iris::base_link</child>
      <pose>0 0 0 0 -0 0</pose>
      <physics>
        <ode>
          <limit>
            <cfm>0</cfm>
            <erp>0.2</erp>
          </limit>
          <suspension>
            <cfm>0</cfm>
            <erp>0.2</erp>
          </suspension>
        </ode>
      </physics>
    </joint>
    <static>0</static>
    <allow_auto_disable>1</allow_auto_disable>
    <plugin name='gimbal_small_2d' filename='libGimbalSmall2dPlugin.so'>
      <joint>iris_standoff_camera::gimbal_small_2d::tilt_joint</joint>
    </plugin>
    <plugin name='sd_drone_plugin' filename='libsd_drone_plugin.so'>
      <ros>
        <namespace>drones/drone_0</namespace>
      </ros>
      <link_name_rotor_0>iris_standoff_camera::iris::rotor_0</link_name_rotor_0>
      <link_name_rotor_1>iris_standoff_camera::iris::rotor_1</link_name_rotor_1>
      <link_name_rotor_2>iris_standoff_camera::iris::rotor_2</link_name_rotor_2>
      <link_name_rotor_3>iris_standoff_camera::iris::rotor_3</link_name_rotor_3>
      <max_vel>10 10 5</max_vel>
    </plugin>
  </model>
</sdf>
